Workbook

Sheet خلاصه
A1: خلاصه گزارش پوشش کدهای ژنریک — فایل‌های قیمت پیام‌داروساز
A2: بر اساس ۲۰۲ فایل اکسل تغییرات قیمت دانلود‌شده از پیام‌داروساز (Drug Exel)
A4: گزارش ۱: پوشش کدهای ژنریک تی‌تک
A5: تعداد کل کد ژنریک یکتا در تی‌تک | B5: 3983
A6: تعداد کد ژنریک یکتا در فایل‌های پیام | B6: 2441
A7: تعداد کدهای تی‌تک که در فایل‌های پیام هم هست | B7: =COUNTIF('پوشش تی‌تک'!C5:C3987,"بله")
A8: درصد پوشش تی‌تک توسط فایل‌های پیام | B8: =B7/B5
A10: گزارش ۲: پوشش کدهای ژنریک موجود در آریا (خروجی زنده سرور)
A11: تعداد کل کد ژنریک یکتا (غیرصفر) در آریا — خروجی زنده SQL از جدول Kala | B11: 3966
A12: تعداد کد ژنریک یکتا در فایل‌های پیام | B12: 2441
A13: تعداد کدهای آریا که در فایل‌های پیام هم هست | B13: =COUNTIF('پوشش کد ژنریک آریا'!C6:C3971,"بله")
A14: درصد پوشش کدهای آریا توسط فایل‌های پیام | B14: =B13/B11
A16: منبع داده‌ها
A17: گزارش ۱ (تی‌تک): از فایل «اقلام تی‌تک - دارو.xlsx» که خودتان آپلود کردید. گزارش ۲ (آریا): مستقیماً از سرور SQL زنده (SERVER، دیتابیس drug، جدول Kala) در تاریخ 1405/07/01 گرفته شد — یعنی جدیدترین وضعیت موجود، شامل کالاهای مکملی که اخیراً وارد شده‌اند. ۱۳۴ کد که به دو شکل با/بدون صفر ابتدایی ثبت شده بودند، یکسان‌سازی و به‌عنوان یک کد شمرده شدند (۴۱۰۰ ردیف خام → ۳۹۶۶ کد یکتای واقعی).

Sheet کدهای پیام‌داروساز
A1: کد ژنریک
A2: 1
A3: 3
A4: 4
A5: 5
A6: 6
A7: 7
A8: 8
A9: 11
A10: 17
A11: 18
A12: 19
A13: 20
... A2442: 53679

Sheet پوشش تی‌تک
A1: پوشش کدهای ژنریک تی‌تک توسط فایل‌های پیام‌داروساز
A2: تعداد کل کد ژنریک یکتا در فایل تی‌تک: 3983 | تعداد یکتا در فایل‌های پیام: 2441
A4: کد ژنریک | B4: نام ژنریک (تی‌تک) | C4: موجود در فایل‌های پیام؟
A5: 1 | B5: ACETAMINOPHEN / CAFFEINE / ASA TABLET ORAL 162.5 mg/32.5 mg/325 mg | C5: =IF(COUNTIF('کدهای پیام‌داروساز'!$A$2:$A$2442,A5)>0,"بله","خیر")
A6: 3 | B6: ACETAMINOPHEN SOLUTION, DROPS ORAL 100 mg/1mL 15 mL | C6: =IF(COUNTIF('کدهای پیام‌داروساز'!$A$2:$A$2442,A6)>0,"بله","خیر")
A7: 4 | B7: ACETAMINOPHEN SOLUTION ORAL 120 mg/5mL 60 mL | C7: =IF(COUNTIF('کدهای پیام‌داروساز'!$A$2:$A$2442,A7)>0,"بله","خیر")
A8: 5 | B8: ACETAMINOPHEN SUSPENSION ORAL 120 mg/5mL 120 mL | C8: =IF(COUNTIF('کدهای پیام‌داروساز'!$A$2:$A$2442,A8)>0,"بله","خیر")
A9: 6 | B9: ACETAMINOPHEN SUPPOSITORY RECTAL 125 mg | C9: =IF(COUNTIF('کدهای پیام‌داروساز'!$A$2:$A$2442,A9)>0,"بله","خیر")
A10: 7 | B10: ACETAMINOPHEN TABLET ORAL 325 mg | C10: =IF(COUNTIF('کدهای پیام‌داروساز'!$A$2:$A$2442,A10)>0,"بله","خیر")
A11: 8 | B11: ACETAMINOPHEN SUPPOSITORY RECTAL 325 mg | C11: =IF(COUNTIF('کدهای پیام‌داروساز'!$A$2:$A$2442,A11)>0,"بله","خیر")
A12: 9 | B12: ACETAMINOPHEN TABLET, ORALLY DISINTEGRATING ORAL 80 mg | C12: =IF(COUNTIF('کدهای پیام‌داروساز'!$A$2:$A$2442,A12)>0,"بله","خیر")
A13: 11 | B13: ACETAZOLAMIDE TABLET ORAL 250 mg | C13: =IF(COUNTIF('کدهای پیام‌داروساز'!$A$2:$A$2442,A13)>0,"بله","خیر")
A14: 12 | B14: ACETAZOLAMIDE INJECTION, POWDER, FOR SOLUTION PARENTERAL 500 mg | C14: =IF(COUNTIF('کدهای پیام‌داروساز'!$A$2:$A$2442,A14)>0,"بله","خیر")
A15: 15 | B15: ACETYLCHOLINE CHLORIDE INJECTION OPHTHALMIC 1 % 2 mL | C15: =IF(COUNTIF('کدهای پیام‌داروساز'!$A$2:$A$2442,A15)>0,"بله","خیر")
A16: 17 | B16: ACITRETIN CAPSULE ORAL 10 mg | C16: =IF(COUNTIF('کدهای پیام‌داروساز'!$A$2:$A$2442,A16)>0,"بله","خیر")
... A2610: 51946 | B2610: ATAZANAVIR / RITONAVIR TABLET ORAL 300 mg/100 mg | C2610: =IF(COUNTIF('کدهای پیام‌داروساز'!$A$2:$A$2442,A2610)>0,"بله","خیر")
A2611: 51947 | C2611: =IF(COUNTIF('کدهای پیام‌داروساز'!$A$2:$A$2442,A2611)>0,"بله","خیر")
A2612: 51948 | B2612: DOLUTEGRAVIR TABLET ORAL 50 mg | C2612: =IF(COUNTIF('کدهای پیام‌داروساز'!$A$2:$A$2442,A2612)>0,"بله","خیر")
A2613: 51949 | B2613: QUININE SULFATE TABLET ORAL 300 mg | C2613: =IF(COUNTIF('کدهای پیام‌داروساز'!$A$2:$A$2442,A2613)>0,"بله","خیر")
A2614: 51950 | B2614: CHLOROQUINE PHOSPHATE SOLUTION ORAL 80 mg/5mL 60 mL | C2614: =IF(COUNTIF('کدهای پیام‌داروساز'!$A$2:$A$2442,A2614)>0,"بله","خیر")
A2615: 51951 | B2615: FACTOR IX INJECTION, POWDER, LYOPHILIZED, FOR SOLUTION PARENTERAL 600 [iU] | C2615: =IF(COUNTIF('کدهای پیام‌داروساز'!$A$2:$A$2442,A2615)>0,"بله","خیر")
A2616: 51952 | B2616: ADULT COLD PREPARATIONS (7-23) TABLET ORAL 15 mg/2 mg/5 mg/500 mg | C2616: =IF(COUNTIF('کدهای پیام‌داروساز'!$A$2:$A$2442,A2616)>0,"بله","خیر")
A2617: 51953 | B2617: DEFERASIROX TABLET ORAL 90 mg | C2617: =IF(COUNTIF('کدهای پیام‌داروساز'!$A$2:$A$2442,A2617)>0,"بله","خیر")
A2618: 51954 | B2618: DEFERASIROX TABLET ORAL 180 mg | C2618: =IF(COUNTIF('کدهای پیام‌داروساز'!$A$2:$A$2442,A2618)>0,"بله","خیر")
A2619: 51955 | B2619: DEFERASIROX TABLET ORAL 360 mg | C2619: =IF(COUNTIF('کدهای پیام‌داروساز'!$A$2:$A$2442,A2619)>0,"بله","خیر")
A2620: 51956 | B2620: MOMETASONE FUROATE SPRAY, SUSPENSION NASAL 0.05 % 14 mL | C2620: =IF(COUNTIF('کدهای پیام‌داروساز'!$A$2:$A$2442,A2620)>0,"بله","خیر")
A2621: 51957 | B2621: EPOETIN INJECTION PARENTERAL 10000 [iU]/1mL 0.4 mL | C2621: =IF(COUNTIF('کدهای پیام‌داروساز'!$A$2:$A$2442,A2621)>0,"بله","خیر")
A2622: 51958 | B2622: POLYETHYLENE GLYCOL - ELECTROLYTE 1 POWDER, FOR SOLUTION ORAL 13.125 g/0.3507 g/0.1785 g/0.0466 g 13.87 g | C2622: =IF(COUNTIF('کدهای پیام‌داروساز'!$A$2:$A$2442,A2622)>0,"بله","خیر")
A2623: 51960 | B2623: AZITHROMYCIN POWDER, FOR SUSPENSION ORAL 100 mg/5mL 30 mL | C2623: =IF(COUNTIF('کدهای پیام‌داروساز'!$A$2:$A$2442,A2623)>0,"بله","خیر")
... A3987: 53787 | B3987: ACETAMINOPHEN SUSPENSION ORAL 160 mg/5mL 120 mL | C3987: =IF(COUNTIF('کدهای پیام‌داروساز'!$A$2:$A$2442,A3987)>0,"بله","خیر")

Sheet پوشش کد ژنریک آریا
A1: پوشش کدهای ژنریک موجود در آریا (خروجی زنده سرور) توسط فایل‌های پیام‌داروساز
A2: تعداد کل کد ژنریک یکتا (غیرصفر) — خروجی زنده از جدول Kala روی سرور، تاریخ 1405/07/01 (2026-09-22): 3966 | توجه: SQL از روی GenCode به‌صورت متنی گروه‌بندی شده بود و ۱۳۴ کد به دو شکل (با/بدون صفر ابتدایی، مثل 00003 و 3) به‌عنوان تکراری ثبت شده بودند که در این گزارش یکسان‌سازی شدند.
A5: کد ژنریک | B5: نام دارو (آریا) | C5: موجود در فایل‌های پیام؟
A6: 1 | B6: آ.ث.آ قرص خوراکي 162.5 mg/32.5 mg/325 mg - داروسازي ابوريحان | C6: =IF(COUNTIF('کدهای پیام‌داروساز'!$A$2:$A$2442,A6)>0,"بله","خیر")
A7: 3 | B7: استامينوفن قطره 15ML - دنياي بهداشت | C7: =IF(COUNTIF('کدهای پیام‌داروساز'!$A$2:$A$2442,A7)>0,"بله","خیر")
A8: 4 | B8: استاسنس محلول خوراکي 120 mg/5mL 60 mL - تريتا داروي هزاره سوم | C8: =IF(COUNTIF('کدهای پیام‌داروساز'!$A$2:$A$2442,A8)>0,"بله","خیر")
A9: 5 | B9: پاراتل سوسپانسيون خوراکي | C9: =IF(COUNTIF('کدهای پیام‌داروساز'!$A$2:$A$2442,A9)>0,"بله","خیر")
A10: 6 | B10: آفي ستامول 125 (استامينوفن) شياف - آوندفر | C10: =IF(COUNTIF('کدهای پیام‌داروساز'!$A$2:$A$2442,A10)>0,"بله","خیر")
A11: 7 | B11: استاگروفن قرص خوراکي 325 mg | C11: =IF(COUNTIF('کدهای پیام‌داروساز'!$A$2:$A$2442,A11)>0,"بله","خیر")
A12: 8 | B12: استامينوفن شياف مقعدي 325 mg | C12: =IF(COUNTIF('کدهای پیام‌داروساز'!$A$2:$A$2442,A12)>0,"بله","خیر")
A13: 9 | B13: تايني فن قرص بازشونده در دهان خوراکي 80 mg - تدبير کالاي جم | C13: =IF(COUNTIF('کدهای پیام‌داروساز'!$A$2:$A$2442,A13)>0,"بله","خیر")
A14: 11 | B14: استازولاميد قرص خوراکي 250 mg | C14: =IF(COUNTIF('کدهای پیام‌داروساز'!$A$2:$A$2442,A14)>0,"بله","خیر")
A15: 12 | B15: دياموکس پودر براي تهيه محلول تزريقي پرنترال 500 mg [Amb'a'1'U] - فوريتهاي سينا آرات گستر | C15: =IF(COUNTIF('کدهای پیام‌داروساز'!$A$2:$A$2442,A15)>0,"بله","خیر")
A16: 15 | B16: ميووزين تزريقي چشمي 1 % 2 mg - تدبير کالاي جم | C16: =IF(COUNTIF('کدهای پیام‌داروساز'!$A$2:$A$2442,A16)>0,"بله","خیر")
A17: 17 | B17: نئوتيکازون - نواترتين 10(آسيترتين)کپسول-داگلاس | C17: =IF(COUNTIF('کدهای پیام‌داروساز'!$A$2:$A$2442,A17)>0,"بله","خیر")
... A3971: 86902457 | B3971: ژل ليفت ابرو رنکل | C3971: =IF(COUNTIF('کدهای پیام‌داروساز'!$A$2:$A$2442,A3971)>0,"بله","خیر")

Sheet در پیام نیست
A1: ردیف | B1: کد ژنریک | C1: نام ژنریک (تی‌تک) | D1: نام دارو (آریا) | E1: منبع | F1: نتیجه جستجو در پیام
A2: 1 | B2: 9 | C2: ACETAMINOPHEN TABLET, ORALLY DISINTEGRATING ORAL 80 mg | D2: تايني فن قرص بازشونده در دهان خوراکي 80 mg - تدبير کالاي جم | E2: تی‌تک و آریا
A3: 2 | B3: 12 | C3: ACETAZOLAMIDE INJECTION, POWDER, FOR SOLUTION PARENTERAL 500 mg | D3: دياموکس پودر براي تهيه محلول تزريقي پرنترال 500 mg [Amb'a'1'U] - فوريتهاي سينا آرات گستر | E3: تی‌تک و آریا
A4: 3 | B4: 15 | C4: ACETYLCHOLINE CHLORIDE INJECTION OPHTHALMIC 1 % 2 mL | D4: ميووزين تزريقي چشمي 1 % 2 mg - تدبير کالاي جم | E4: تی‌تک و آریا
A5: 4 | B5: 25 | D5: قرص گريپ کات کلد(سرماخوردگي بزرگسال) | E5: فقط آریا
A6: 5 | B6: 28 | C6: ALBUMIN (HUMAN) INJECTION, SOLUTION PARENTERAL 5 % 100 mL | D6: ايمونوگلوبولين نرمال انساني محلول تزريقي پرنترال 5 % 100 mL - اکسين دارو پارس | E6: تی‌تک و آریا
A7: 6 | B7: 45 | C7: ALUMINIUM HYDROXIDE TABLET, CHEWABLE ORAL 300 mg | D7: آلومينيوم هيدروکسايد قرص جويدني خوراکي 300 mg - لابراتوارهاي رازک | E7: تی‌تک و آریا
A8: 7 | B8: 57 | C8: AMINO ACID 5% (1) INJECTION, SOLUTION INTRAVENOUS 2.25 mg/4.45 mg/3.5 mg/1.9 mg/2.55 mg/2.05 mg/0.9 mg/2.4 mg/4.6 mg/2.6 mg/6.85 mg/3.95 mg/1.86 mg/0.65 mg/0.36 mg/2.3 mg/1.6 mg/4.45 mg/1.2 mg/0.3 mg/0.43 mg/1 mL/1mL 500 mL | E8: فقط تی‌تک
A9: 8 | B9: 88 | C9: ANTHOCYANOSIDE A TABLET ORAL 100 mg/5 mg | D9: آنتوسيانوزيد آ قرص خوراکي 100 mg/5 mg - مهردارو | E9: تی‌تک و آریا
A10: 9 | B10: 91 | C10: FACTOR IX INJECTION, POWDER, LYOPHILIZED, FOR SOLUTION PARENTERAL 1000 [iU] | D10: آيمافيکس پودر لئوفيليزه براي تهيه محلول تزريقي پرنترال 1000 [iU] [iU] - بهستان دارو | E10: تی‌تک و آریا
A11: 10 | B11: 98 | D11: آنتي هيستامين دکونژستات قرص - جالينوس | E11: فقط آریا
A12: 11 | B12: 105 | D12: تيرلوز (اشک مصنوعي) 10 م ل قطره چشمي - سينا دارو | E12: فقط آریا
A13: 12 | B13: 110 | C13: ASA / CODEINE PHOSPHATE TABLET ORAL 500 mg/10 mg | E13: فقط تی‌تک
A14: 13 | B14: 112 | C14: ASA (ACETYLSALICYLIC ACID) TABLET ORAL 500 mg | D14: آ اس آ قرص خوراکي 500 mg - پارس دارو | E14: تی‌تک و آریا
A15: 14 | B15: 124 | D15: ب کمپلکس 60 م ل شربت - ايران دارو | E15: فقط آریا
A16: 15 | B16: 135 | C16: BELLADONNA PB ELIXIR ORAL 19.4 ug/6.5 ug/103.7 ug/16.2 mg/5mL 60 mL | D16: بلادونا پي بي الگزير خوراکي 60 mL - لابراتوارهاي شهردارو | E16: تی‌تک و آریا
A17: 16 | B17: 138 | C17: BENZOYL PEROXIDE LOTION TOPICAL 10 % 30 mL | E17: فقط تی‌تک
A18: 17 | B18: 181 | C18: BUPIVACAINE HYDROCHLORIDE INJECTION PARENTERAL 0.25 % 20 mL | E18: فقط تی‌تک
A19: 18 | B19: 186 | C19: BUSULFAN TABLET ORAL 2 mg | D19: بوسلون قرص خوراکي 2 mg - رايان دارو ايرانيان | E19: تی‌تک و آریا
A20: 19 | B20: 187 | D20: سي-لاکس قرص-دينه (قوطي) | E20: فقط آریا
A21: 20 | B21: 197 | D21: کلسيم سيترات قرص - آپوويتال | E21: فقط آریا
A22: 21 | B22: 199 | D22: کلسيم فورت 500 م گ جوشان - مينو | E22: فقط آریا
A23: 22 | B23: 202 | D23: کالاندولا کرم موضعي 15 گرم - دينه | E23: فقط آریا
A24: 23 | B24: 204 | C24: CAPREOMYCIN (AS SULFATE) INJECTION, POWDER, FOR SUSPENSION INTRAMUSCULAR 1 g | E24: فقط تی‌تک
A25: 24 | B25: 219 | C25: CARMUSTINE INJECTION, POWDER, FOR SOLUTION PARENTERAL 100 mg | D25: بيکنو پودر براي تهيه محلول تزريقي پرنترال 100 mg mg - بازرگاني سها کيش | E25: تی‌تک و آریا
A26: 25 | B26: 228 | C26: CEFIXIME POWDER, FOR SUSPENSION ORAL 50 mg/5 mL 30 mL | D26: اي- سف پودر براي تهيه سوسپانسيون خوراکي 50 mg/5 mL 30 mg - بازرگاني سها کيش | E26: تی‌تک و آریا
A27: 26 | B27: 238 | C27: CEFTRIAXONE (AS SODIUM) INJECTION, POWDER, FOR SOLUTION PARENTERAL 250 mg | D27: سفتريانا پودر براي تهيه محلول تزريقي پرنترال 250 mg mg - داروسازي دانا | E27: تی‌تک و آریا
A28: 27 | B28: 260 | C28: CHILDREN COLD TABLET, CHEWABLE ORAL 80 mg/0.5 mg/7.5 mg | E28: فقط تی‌تک
A29: 28 | B29: 270 | D29: ايرشا (کلرهگزيدين) 0.2% 250 م ل دهانشويه - شفا | E29: فقط آریا
A30: 29 | B30: 302 | C30: CISPLATIN INJECTION, SOLUTION, CONCENTRATE INTRAVENOUS 0.5 mg/1mL 100 mL | E30: فقط تی‌تک
A31: 30 | B31: 315 | C31: CLOBUTINOL HYDROCHLORIDE TABLET ORAL 40 mg | E31: فقط تی‌تک
A32: 31 | B32: 316 | C32: CLOBUTINOL HYDROCHLORIDE SOLUTION, DROPS ORAL 60 mg/1mL 15 mL | E32: فقط تی‌تک
A33: 32 | B33: 330 | C33: CLOXACILLIN (AS SODIUM) INJECTION, POWDER, FOR SOLUTION PARENTERAL 250 mg | D33: کلوگزاسيل پودر براي تهيه محلول تزريقي پرنترال 250 mg mg - داروسازي جابرابن حيان | E33: تی‌تک و آریا
A34: 33 | B34: 344 | D34: کل تار (درمين) 1 درصد 150 م ل شامپو - گيلارانکو | E34: فقط آریا
A35: 34 | B35: 346 | C35: COAL TAR LOTION TOPICAL 5 % 60 mL | D35: تاروزيس لوسيون موضعي 5 % 60 mL - گيلارانکو | E35: تی‌تک و آریا
A36: 35 | B36: 364 | C36: CROMOLYN SODIUM CAPSULE RESPIRATORY 20 mg | D36: لومودال کپسول استنشاقي 20 mg | E36: تی‌تک و آریا
A37: 36 | B37: 371 | C37: CYCLOSERINE CAPSULE ORAL 250 mg | D37: سيکلوسرين کپسول خوراکي 250 mg - بازرگاني سها کيش | E37: تی‌تک و آریا
A38: 37 | B38: 382 | C38: DANTROLENE SODIUM INJECTION, POWDER, FOR SOLUTION PARENTERAL 20 mg | D38: دانتروالس پودر براي تهيه محلول تزريقي پرنترال 20 mg mg - فرفيون دارو | E38: تی‌تک و آریا
A39: 38 | B39: 383 | C39: DAPSONE TABLET ORAL 100 mg | D39: قرص داپسون 100 ميلي گرم | E39: تی‌تک و آریا
A40: 39 | B40: 384 | C40: DAUNORUBICIN (AS HYDROCHLORIDE) INJECTION, POWDER, FOR SOLUTION PARENTERAL 20 mg | D40: دائنئون پودر براي تهيه محلول تزريقي پرنترال 20 mg mg - آرام کيمياي کاسپين | E40: تی‌تک و آریا
...
